Workbook

Sheet DATA ROOM RUKOST
A1: JUMLAH KAMAR | B1: NO. UNIT | C1: NO. KAMAR | D1: TENANT | E1: KELAMIN | F1: STATUS | G1: WAKTU SEWA/TAHUN | H1: RATE | I1: CHECK IN | J1: CHECK OUT | K1: TANGGAL BULAN 2026
A2: 1 | B2: 01 B:5 A:6 Putri | C2: 1 | F2: =IF(D2="","Vacant","Inhouse") -> Vacant | H2: =G2*$G$127 -> 0 | K2: 1 | L2: 2 | M2: 3 | N2: 4 | O2: 5 | P2: 6 | Q2: 7 | R2: 8 | S2: 9 | T2: 10 | U2: 11 | V2: 12 | W2: 13 | X2: 14 | Y2: 15 | Z2: 16 | AA2: 17 | AB2: 18 | AC2: 19 | AD2: 20 | AE2: 21 | AF2: 22 | AG2: 23 | AH2: 24 | AI2: 25 | AJ2: 26 | AK2: 27 | AL2: 28 | AM2: 29 | AN2: 30 | AO2: 31
A3: 2 | C3: 2 | F3: =IF(D3="","Vacant","Inhouse") -> Vacant | H3: =G3*$G$127 -> 0 | K3: 1 | L3: 2 | M3: 3 | N3: 4 | O3: 5 | P3: 6 | Q3: 7 | R3: 8 | S3: 9 | T3: 10 | U3: 11 | V3: 12 | W3: 13 | X3: 14 | Y3: 15 | Z3: 16 | AA3: 17 | AB3: 18 | AC3: 19 | AD3: 20 | AE3: 21 | AF3: 22 | AG3: 23 | AH3: 24 | AI3: 25 | AJ3: 26 | AK3: 27 | AL3: 28 | AM3: 29 | AN3: 30 | AO3: 31
A4: 3 | C4: 3 | F4: =IF(D4="","Vacant","Inhouse") -> Vacant | H4: =G4*$G$127 -> 0 | K4: 1 | L4: 2 | M4: 3 | N4: 4 | O4: 5 | P4: 6 | Q4: 7 | R4: 8 | S4: 9 | T4: 10 | U4: 11 | V4: 12 | W4: 13 | X4: 14 | Y4: 15 | Z4: 16 | AA4: 17 | AB4: 18 | AC4: 19 | AD4: 20 | AE4: 21 | AF4: 22 | AG4: 23 | AH4: 24 | AI4: 25 | AJ4: 26 | AK4: 27 | AL4: 28 | AM4: 29 | AN4: 30 | AO4: 31
A5: 4 | C5: 4 | F5: =IF(D5="","Vacant","Inhouse") -> Vacant | H5: =G5*$G$127 -> 0 | K5: 1 | L5: 2 | M5: 3 | N5: 4 | O5: 5 | P5: 6 | Q5: 7 | R5: 8 | S5: 9 | T5: 10 | U5: 11 | V5: 12 | W5: 13 | X5: 14 | Y5: 15 | Z5: 16 | AA5: 17 | AB5: 18 | AC5: 19 | AD5: 20 | AE5: 21 | AF5: 22 | AG5: 23 | AH5: 24 | AI5: 25 | AJ5: 26 | AK5: 27 | AL5: 28 | AM5: 29 | AN5: 30 | AO5: 31
A6: 5 | C6: 5 | F6: =IF(D6="","Vacant","Inhouse") -> Vacant | H6: =G6*$G$127 -> 0 | K6: 1 | L6: 2 | M6: 3 | N6: 4 | O6: 5 | P6: 6 | Q6: 7 | R6: 8 | S6: 9 | T6: 10 | U6: 11 | V6: 12 | W6: 13 | X6: 14 | Y6: 15 | Z6: 16 | AA6: 17 | AB6: 18 | AC6: 19 | AD6: 20 | AE6: 21 | AF6: 22 | AG6: 23 | AH6: 24 | AI6: 25 | AJ6: 26 | AK6: 27 | AL6: 28 | AM6: 29 | AN6: 30 | AO6: 31
A7: 6 | C7: 6 | F7: =IF(D7="","Vacant","Inhouse") -> Vacant | H7: =G7*$G$127 -> 0 | K7: 1 | L7: 2 | M7: 3 | N7: 4 | O7: 5 | P7: 6 | Q7: 7 | R7: 8 | S7: 9 | T7: 10 | U7: 11 | V7: 12 | W7: 13 | X7: 14 | Y7: 15 | Z7: 16 | AA7: 17 | AB7: 18 | AC7: 19 | AD7: 20 | AE7: 21 | AF7: 22 | AG7: 23 | AH7: 24 | AI7: 25 | AJ7: 26 | AK7: 27 | AL7: 28 | AM7: 29 | AN7: 30 | AO7: 31
A8: 7 | C8: 7 | F8: =IF(D8="","Vacant","Inhouse") -> Vacant | H8: =G8*$G$127 -> 0 | K8: 1 | L8: 2 | M8: 3 | N8: 4 | O8: 5 | P8: 6 | Q8: 7 | R8: 8 | S8: 9 | T8: 10 | U8: 11 | V8: 12 | W8: 13 | X8: 14 | Y8: 15 | Z8: 16 | AA8: 17 | AB8: 18 | AC8: 19 | AD8: 20 | AE8: 21 | AF8: 22 | AG8: 23 | AH8: 24 | AI8: 25 | AJ8: 26 | AK8: 27 | AL8: 28 | AM8: 29 | AN8: 30 | AO8: 31
A9: 8 | C9: 8 | F9: =IF(D9="","Vacant","Inhouse") -> Vacant | H9: =G9*$G$127 -> 0 | K9: 1 | L9: 2 | M9: 3 | N9: 4 | O9: 5 | P9: 6 | Q9: 7 | R9: 8 | S9: 9 | T9: 10 | U9: 11 | V9: 12 | W9: 13 | X9: 14 | Y9: 15 | Z9: 16 | AA9: 17 | AB9: 18 | AC9: 19 | AD9: 20 | AE9: 21 | AF9: 22 | AG9: 23 | AH9: 24 | AI9: 25 | AJ9: 26 | AK9: 27 | AL9: 28 | AM9: 29 | AN9: 30 | AO9: 31
A10: 9 | C10: 9 | F10: =IF(D10="","Vacant","Inhouse") -> Vacant | H10: =G10*$G$127 -> 0 | K10: 1 | L10: 2 | M10: 3 | N10: 4 | O10: 5 | P10: 6 | Q10: 7 | R10: 8 | S10: 9 | T10: 10 | U10: 11 | V10: 12 | W10: 13 | X10: 14 | Y10: 15 | Z10: 16 | AA10: 17 | AB10: 18 | AC10: 19 | AD10: 20 | AE10: 21 | AF10: 22 | AG10: 23 | AH10: 24 | AI10: 25 | AJ10: 26 | AK10: 27 | AL10: 28 | AM10: 29 | AN10: 30 | AO10: 31
A11: 10 | C11: 10 | F11: =IF(D11="","Vacant","Inhouse") -> Vacant | H11: =G11*$G$127 -> 0 | K11: 1 | L11: 2 | M11: 3 | N11: 4 | O11: 5 | P11: 6 | Q11: 7 | R11: 8 | S11: 9 | T11: 10 | U11: 11 | V11: 12 | W11: 13 | X11: 14 | Y11: 15 | Z11: 16 | AA11: 17 | AB11: 18 | AC11: 19 | AD11: 20 | AE11: 21 | AF11: 22 | AG11: 23 | AH11: 24 | AI11: 25 | AJ11: 26 | AK11: 27 | AL11: 28 | AM11: 29 | AN11: 30 | AO11: 31
A12: 11 | C12: 11 | F12: =IF(D12="","Vacant","Inhouse") -> Vacant | H12: =G12*$G$127 -> 0 | K12: 1 | L12: 2 | M12: 3 | N12: 4 | O12: 5 | P12: 6 | Q12: 7 | R12: 8 | S12: 9 | T12: 10 | U12: 11 | V12: 12 | W12: 13 | X12: 14 | Y12: 15 | Z12: 16 | AA12: 17 | AB12: 18 | AC12: 19 | AD12: 20 | AE12: 21 | AF12: 22 | AG12: 23 | AH12: 24 | AI12: 25 | AJ12: 26 | AK12: 27 | AL12: 28 | AM12: 29 | AN12: 30 | AO12: 31
A13: 12 | B13: 02 B:4 A:4 Putra | C13: 1 | F13: =IF(D13="","Vacant","Inhouse") -> Vacant | H13: =G13*$G$127 -> 0 | K13: 1 | L13: 2 | M13: 3 | N13: 4 | O13: 5 | P13: 6 | Q13: 7 | R13: 8 | S13: 9 | T13: 10 | U13: 11 | V13: 12 | W13: 13 | X13: 14 | Y13: 15 | Z13: 16 | AA13: 17 | AB13: 18 | AC13: 19 | AD13: 20 | AE13: 21 | AF13: 22 | AG13: 23 | AH13: 24 | AI13: 25 | AJ13: 26 | AK13: 27 | AL13: 28 | AM13: 29 | AN13: 30 | AO13: 31
A14: 13 | C14: 2 | F14: =IF(D14="","Vacant","Inhouse") -> Vacant | H14: =G14*$G$127 -> 0 | K14: 1 | L14: 2 | M14: 3 | N14: 4 | O14: 5 | P14: 6 | Q14: 7 | R14: 8 | S14: 9 | T14: 10 | U14: 11 | V14: 12 | W14: 13 | X14: 14 | Y14: 15 | Z14: 16 | AA14: 17 | AB14: 18 | AC14: 19 | AD14: 20 | AE14: 21 | AF14: 22 | AG14: 23 | AH14: 24 | AI14: 25 | AJ14: 26 | AK14: 27 | AL14: 28 | AM14: 29 | AN14: 30 | AO14: 31
A15: 14 | C15: 3 | F15: =IF(D15="","Vacant","Inhouse") -> Vacant | H15: =G15*$G$127 -> 0 | K15: 1 | L15: 2 | M15: 3 | N15: 4 | O15: 5 | P15: 6 | Q15: 7 | R15: 8 | S15: 9 | T15: 10 | U15: 11 | V15: 12 | W15: 13 | X15: 14 | Y15: 15 | Z15: 16 | AA15: 17 | AB15: 18 | AC15: 19 | AD15: 20 | AE15: 21 | AF15: 22 | AG15: 23 | AH15: 24 | AI15: 25 | AJ15: 26 | AK15: 27 | AL15: 28 | AM15: 29 | AN15: 30 | AO15: 31
A16: 15 | C16: 4 | F16: =IF(D16="","Vacant","Inhouse") -> Vacant | H16: =G16*$G$127 -> 0 | K16: 1 | L16: 2 | M16: 3 | N16: 4 | O16: 5 | P16: 6 | Q16: 7 | R16: 8 | S16: 9 | T16: 10 | U16: 11 | V16: 12 | W16: 13 | X16: 14 | Y16: 15 | Z16: 16 | AA16: 17 | AB16: 18 | AC16: 19 | AD16: 20 | AE16: 21 | AF16: 22 | AG16: 23 | AH16: 24 | AI16: 25 | AJ16: 26 | AK16: 27 | AL16: 28 | AM16: 29 | AN16: 30 | AO16: 31
A17: 16 | C17: 5 | F17: =IF(D17="","Vacant","Inhouse") -> Vacant | H17: =G17*$G$127 -> 0 | K17: 1 | L17: 2 | M17: 3 | N17: 4 | O17: 5 | P17: 6 | Q17: 7 | R17: 8 | S17: 9 | T17: 10 | U17: 11 | V17: 12 | W17: 13 | X17: 14 | Y17: 15 | Z17: 16 | AA17: 17 | AB17: 18 | AC17: 19 | AD17: 20 | AE17: 21 | AF17: 22 | AG17: 23 | AH17: 24 | AI17: 25 | AJ17: 26 | AK17: 27 | AL17: 28 | AM17: 29 | AN17: 30 | AO17: 31
A18: 17 | C18: 6 | F18: =IF(D18="","Vacant","Inhouse") -> Vacant | H18: =G18*$G$127 -> 0 | K18: 1 | L18: 2 | M18: 3 | N18: 4 | O18: 5 | P18: 6 | Q18: 7 | R18: 8 | S18: 9 | T18: 10 | U18: 11 | V18: 12 | W18: 13 | X18: 14 | Y18: 15 | Z18: 16 | AA18: 17 | AB18: 18 | AC18: 19 | AD18: 20 | AE18: 21 | AF18: 22 | AG18: 23 | AH18: 24 | AI18: 25 | AJ18: 26 | AK18: 27 | AL18: 28 | AM18: 29 | AN18: 30 | AO18: 31
A19: 18 | C19: 7 | F19: =IF(D19="","Vacant","Inhouse") -> Vacant | H19: =G19*$G$127 -> 0 | K19: 1 | L19: 2 | M19: 3 | N19: 4 | O19: 5 | P19: 6 | Q19: 7 | R19: 8 | S19: 9 | T19: 10 | U19: 11 | V19: 12 | W19: 13 | X19: 14 | Y19: 15 | Z19: 16 | AA19: 17 | AB19: 18 | AC19: 19 | AD19: 20 | AE19: 21 | AF19: 22 | AG19: 23 | AH19: 24 | AI19: 25 | AJ19: 26 | AK19: 27 | AL19: 28 | AM19: 29 | AN19: 30 | AO19: 31
A20: 19 | C20: 8 | F20: =IF(D20="","Vacant","Inhouse") -> Vacant | H20: =G20*$G$127 -> 0 | K20: 1 | L20: 2 | M20: 3 | N20: 4 | O20: 5 | P20: 6 | Q20: 7 | R20: 8 | S20: 9 | T20: 10 | U20: 11 | V20: 12 | W20: 13 | X20: 14 | Y20: 15 | Z20: 16 | AA20: 17 | AB20: 18 | AC20: 19 | AD20: 20 | AE20: 21 | AF20: 22 | AG20: 23 | AH20: 24 | AI20: 25 | AJ20: 26 | AK20: 27 | AL20: 28 | AM20: 29 | AN20: 30 | AO20: 31
A21: 20 | B21: 03 B:4 B:4 Putri | C21: 1 | F21: =IF(D21="","Vacant","Inhouse") -> Vacant | H21: =G21*$G$127 -> 0 | K21: 1 | L21: 2 | M21: 3 | N21: 4 | O21: 5 | P21: 6 | Q21: 7 | R21: 8 | S21: 9 | T21: 10 | U21: 11 | V21: 12 | W21: 13 | X21: 14 | Y21: 15 | Z21: 16 | AA21: 17 | AB21: 18 | AC21: 19 | AD21: 20 | AE21: 21 | AF21: 22 | AG21: 23 | AH21: 24 | AI21: 25 | AJ21: 26 | AK21: 27 | AL21: 28 | AM21: 29 | AN21: 30 | AO21: 31
A22: 21 | C22: 2 | F22: =IF(D22="","Vacant","Inhouse") -> Vacant | H22: =G22*$G$127 -> 0 | K22: 1 | L22: 2 | M22: 3 | N22: 4 | O22: 5 | P22: 6 | Q22: 7 | R22: 8 | S22: 9 | T22: 10 | U22: 11 | V22: 12 | W22: 13 | X22: 14 | Y22: 15 | Z22: 16 | AA22: 17 | AB22: 18 | AC22: 19 | AD22: 20 | AE22: 21 | AF22: 22 | AG22: 23 | AH22: 24 | AI22: 25 | AJ22: 26 | AK22: 27 | AL22: 28 | AM22: 29 | AN22: 30 | AO22: 31
A23: 22 | C23: 3 | F23: =IF(D23="","Vacant","Inhouse") -> Vacant | H23: =G23*$G$127 -> 0 | K23: 1 | L23: 2 | M23: 3 | N23: 4 | O23: 5 | P23: 6 | Q23: 7 | R23: 8 | S23: 9 | T23: 10 | U23: 11 | V23: 12 | W23: 13 | X23: 14 | Y23: 15 | Z23: 16 | AA23: 17 | AB23: 18 | AC23: 19 | AD23: 20 | AE23: 21 | AF23: 22 | AG23: 23 | AH23: 24 | AI23: 25 | AJ23: 26 | AK23: 27 | AL23: 28 | AM23: 29 | AN23: 30 | AO23: 31
A24: 23 | C24: 4 | F24: =IF(D24="","Vacant","Inhouse") -> Vacant | H24: =G24*$G$127 -> 0 | K24: 1 | L24: 2 | M24: 3 | N24: 4 | O24: 5 | P24: 6 | Q24: 7 | R24: 8 | S24: 9 | T24: 10 | U24: 11 | V24: 12 | W24: 13 | X24: 14 | Y24: 15 | Z24: 16 | AA24: 17 | AB24: 18 | AC24: 19 | AD24: 20 | AE24: 21 | AF24: 22 | AG24: 23 | AH24: 24 | AI24: 25 | AJ24: 26 | AK24: 27 | AL24: 28 | AM24: 29 | AN24: 30 | AO24: 31
A25: 24 | C25: 5 | F25: =IF(D25="","Vacant","Inhouse") -> Vacant | H25: =G25*$G$127 -> 0 | K25: 1 | L25: 2 | M25: 3 | N25: 4 | O25: 5 | P25: 6 | Q25: 7 | R25: 8 | S25: 9 | T25: 10 | U25: 11 | V25: 12 | W25: 13 | X25: 14 | Y25: 15 | Z25: 16 | AA25: 17 | AB25: 18 | AC25: 19 | AD25: 20 | AE25: 21 | AF25: 22 | AG25: 23 | AH25: 24 | AI25: 25 | AJ25: 26 | AK25: 27 | AL25: 28 | AM25: 29 | AN25: 30 | AO25: 31
A26: 25 | C26: 6 | F26: =IF(D26="","Vacant","Inhouse") -> Vacant | H26: =G26*$G$127 -> 0 | K26: 1 | L26: 2 | M26: 3 | N26: 4 | O26: 5 | P26: 6 | Q26: 7 | R26: 8 | S26: 9 | T26: 10 | U26: 11 | V26: 12 | W26: 13 | X26: 14 | Y26: 15 | Z26: 16 | AA26: 17 | AB26: 18 | AC26: 19 | AD26: 20 | AE26: 21 | AF26: 22 | AG26: 23 | AH26: 24 | AI26: 25 | AJ26: 26 | AK26: 27 | AL26: 28 | AM26: 29 | AN26: 30 | AO26: 31
A27: 26 | C27: 7 | F27: =IF(D27="","Vacant","Inhouse") -> Vacant | H27: =G27*$G$127 -> 0 | K27: 1 | L27: 2 | M27: 3 | N27: 4 | O27: 5 | P27: 6 | Q27: 7 | R27: 8 | S27: 9 | T27: 10 | U27: 11 | V27: 12 | W27: 13 | X27: 14 | Y27: 15 | Z27: 16 | AA27: 17 | AB27: 18 | AC27: 19 | AD27: 20 | AE27: 21 | AF27: 22 | AG27: 23 | AH27: 24 | AI27: 25 | AJ27: 26 | AK27: 27 | AL27: 28 | AM27: 29 | AN27: 30 | AO27: 31
A28: 27 | C28: 8 | F28: =IF(D28="","Vacant","Inhouse") -> Vacant | H28: =G28*$G$127 -> 0 | K28: 1 | L28: 2 | M28: 3 | N28: 4 | O28: 5 | P28: 6 | Q28: 7 | R28: 8 | S28: 9 | T28: 10 | U28: 11 | V28: 12 | W28: 13 | X28: 14 | Y28: 15 | Z28: 16 | AA28: 17 | AB28: 18 | AC28: 19 | AD28: 20 | AE28: 21 | AF28: 22 | AG28: 23 | AH28: 24 | AI28: 25 | AJ28: 26 | AK28: 27 | AL28: 28 | AM28: 29 | AN28: 30 | AO28: 31
A29: 28 | B29: 04 B:3 A:4 Putra | C29: 1 | F29: =IF(D29="","Vacant","Inhouse") -> Vacant | H29: =G29*$G$127 -> 0 | K29: 1 | L29: 2 | M29: 3 | N29: 4 | O29: 5 | P29: 6 | Q29: 7 | R29: 8 | S29: 9 | T29: 10 | U29: 11 | V29: 12 | W29: 13 | X29: 14 | Y29: 15 | Z29: 16 | AA29: 17 | AB29: 18 | AC29: 19 | AD29: 20 | AE29: 21 | AF29: 22 | AG29: 23 | AH29: 24 | AI29: 25 | AJ29: 26 | AK29: 27 | AL29: 28 | AM29: 29 | AN29: 30 | AO29: 31
A30: 29 | C30: 2 | F30: =IF(D30="","Vacant","Inhouse") -> Vacant | H30: =G30*$G$127 -> 0 | K30: 1 | L30: 2 | M30: 3 | N30: 4 | O30: 5 | P30: 6 | Q30: 7 | R30: 8 | S30: 9 | T30: 10 | U30: 11 | V30: 12 | W30: 13 | X30: 14 | Y30: 15 | Z30: 16 | AA30: 17 | AB30: 18 | AC30: 19 | AD30: 20 | AE30: 21 | AF30: 22 | AG30: 23 | AH30: 24 | AI30: 25 | AJ30: 26 | AK30: 27 | AL30: 28 | AM30: 29 | AN30: 30 | AO30: 31
A31: 30 | C31: 3 | F31: =IF(D31="","Vacant","Inhouse") -> Vacant | H31: =G31*$G$127 -> 0 | K31: 1 | L31: 2 | M31: 3 | N31: 4 | O31: 5 | P31: 6 | Q31: 7 | R31: 8 | S31: 9 | T31: 10 | U31: 11 | V31: 12 | W31: 13 | X31: 14 | Y31: 15 | Z31: 16 | AA31: 17 | AB31: 18 | AC31: 19 | AD31: 20 | AE31: 21 | AF31: 22 | AG31: 23 | AH31: 24 | AI31: 25 | AJ31: 26 | AK31: 27 | AL31: 28 | AM31: 29 | AN31: 30 | AO31: 31
A32: 31 | C32: 4 | F32: =IF(D32="","Vacant","Inhouse") -> Vacant | H32: =G32*$G$127 -> 0 | K32: 1 | L32: 2 | M32: 3 | N32: 4 | O32: 5 | P32: 6 | Q32: 7 | R32: 8 | S32: 9 | T32: 10 | U32: 11 | V32: 12 | W32: 13 | X32: 14 | Y32: 15 | Z32: 16 | AA32: 17 | AB32: 18 | AC32: 19 | AD32: 20 | AE32: 21 | AF32: 22 | AG32: 23 | AH32: 24 | AI32: 25 | AJ32: 26 | AK32: 27 | AL32: 28 | AM32: 29 | AN32: 30 | AO32: 31
A33: 32 | C33: 5 | F33: =IF(D33="","Vacant","Inhouse") -> Vacant | H33: =G33*$G$127 -> 0 | K33: 1 | L33: 2 | M33: 3 | N33: 4 | O33: 5 | P33: 6 | Q33: 7 | R33: 8 | S33: 9 | T33: 10 | U33: 11 | V33: 12 | W33: 13 | X33: 14 | Y33: 15 | Z33: 16 | AA33: 17 | AB33: 18 | AC33: 19 | AD33: 20 | AE33: 21 | AF33: 22 | AG33: 23 | AH33: 24 | AI33: 25 | AJ33: 26 | AK33: 27 | AL33: 28 | AM33: 29 | AN33: 30 | AO33: 31
A34: 33 | C34: 6 | F34: =IF(D34="","Vacant","Inhouse") -> Vacant | H34: =G34*$G$127 -> 0 | K34: 1 | L34: 2 | M34: 3 | N34: 4 | O34: 5 | P34: 6 | Q34: 7 | R34: 8 | S34: 9 | T34: 10 | U34: 11 | V34: 12 | W34: 13 | X34: 14 | Y34: 15 | Z34: 16 | AA34: 17 | AB34: 18 | AC34: 19 | AD34: 20 | AE34: 21 | AF34: 22 | AG34: 23 | AH34: 24 | AI34: 25 | AJ34: 26 | AK34: 27 | AL34: 28 | AM34: 29 | AN34: 30 | AO34: 31
A35: 34 | C35: 7 | F35: =IF(D35="","Vacant","Inhouse") -> Vacant | H35: =G35*$G$127 -> 0 | K35: 1 | L35: 2 | M35: 3 | N35: 4 | O35: 5 | P35: 6 | Q35: 7 | R35: 8 | S35: 9 | T35: 10 | U35: 11 | V35: 12 | W35: 13 | X35: 14 | Y35: 15 | Z35: 16 | AA35: 17 | AB35: 18 | AC35: 19 | AD35: 20 | AE35: 21 | AF35: 22 | AG35: 23 | AH35: 24 | AI35: 25 | AJ35: 26 | AK35: 27 | AL35: 28 | AM35: 29 | AN35: 30 | AO35: 31
A36: 35 | B36: 06 B-3 A-4 Putra | C36: 1 | F36: =IF(D36="","Vacant","Inhouse") -> Vacant | H36: =G36*$G$127 -> 0 | K36: 1 | L36: 2 | M36: 3 | N36: 4 | O36: 5 | P36: 6 | Q36: 7 | R36: 8 | S36: 9 | T36: 10 | U36: 11 | V36: 12 | W36: 13 | X36: 14 | Y36: 15 | Z36: 16 | AA36: 17 | AB36: 18 | AC36: 19 | AD36: 20 | AE36: 21 | AF36: 22 | AG36: 23 | AH36: 24 | AI36: 25 | AJ36: 26 | AK36: 27 | AL36: 28 | AM36: 29 | AN36: 30 | AO36: 31
A37: 36 | C37: 2 | F37: =IF(D37="","Vacant","Inhouse") -> Vacant | H37: =G37*$G$127 -> 0 | K37: 1 | L37: 2 | M37: 3 | N37: 4 | O37: 5 | P37: 6 | Q37: 7 | R37: 8 | S37: 9 | T37: 10 | U37: 11 | V37: 12 | W37: 13 | X37: 14 | Y37: 15 | Z37: 16 | AA37: 17 | AB37: 18 | AC37: 19 | AD37: 20 | AE37: 21 | AF37: 22 | AG37: 23 | AH37: 24 | AI37: 25 | AJ37: 26 | AK37: 27 | AL37: 28 | AM37: 29 | AN37: 30 | AO37: 31
A38: 37 | C38: 3 | F38: =IF(D38="","Vacant","Inhouse") -> Vacant | H38: =G38*$G$127 -> 0 | K38: 1 | L38: 2 | M38: 3 | N38: 4 | O38: 5 | P38: 6 | Q38: 7 | R38: 8 | S38: 9 | T38: 10 | U38: 11 | V38: 12 | W38: 13 | X38: 14 | Y38: 15 | Z38: 16 | AA38: 17 | AB38: 18 | AC38: 19 | AD38: 20 | AE38: 21 | AF38: 22 | AG38: 23 | AH38: 24 | AI38: 25 | AJ38: 26 | AK38: 27 | AL38: 28 | AM38: 29 | AN38: 30 | AO38: 31
A39: 38 | C39: 4 | F39: =IF(D39="","Vacant","Inhouse") -> Vacant | H39: =G39*$G$127 -> 0 | K39: 1 | L39: 2 | M39: 3 | N39: 4 | O39: 5 | P39: 6 | Q39: 7 | R39: 8 | S39: 9 | T39: 10 | U39: 11 | V39: 12 | W39: 13 | X39: 14 | Y39: 15 | Z39: 16 | AA39: 17 | AB39: 18 | AC39: 19 | AD39: 20 | AE39: 21 | AF39: 22 | AG39: 23 | AH39: 24 | AI39: 25 | AJ39: 26 | AK39: 27 | AL39: 28 | AM39: 29 | AN39: 30 | AO39: 31
A40: 39 | C40: 5 | F40: =IF(D40="","Vacant","Inhouse") -> Vacant | H40: =G40*$G$127 -> 0 | K40: 1 | L40: 2 | M40: 3 | N40: 4 | O40: 5 | P40: 6 | Q40: 7 | R40: 8 | S40: 9 | T40: 10 | U40: 11 | V40: 12 | W40: 13 | X40: 14 | Y40: 15 | Z40: 16 | AA40: 17 | AB40: 18 | AC40: 19 | AD40: 20 | AE40: 21 | AF40: 22 | AG40: 23 | AH40: 24 | AI40: 25 | AJ40: 26 | AK40: 27 | AL40: 28 | AM40: 29 | AN40: 30 | AO40: 31
...

Sheet KPI DIAGRAM RUKOST
A13: ='DATA ROOM APARTKOST'!A47 -> OCCUPANCY | B13: ='DATA ROOM APARTKOST'!C49 -> REVENUE | C13: ='DATA ROOM APARTKOST'!A58 -> TARGET | D13: ='DATA ROOM APARTKOST'!A51 -> TOTAL KAMAR
A14: ='DATA ROOM RUKOST'!B131 -> 0 | B14: ='DATA ROOM RUKOST'!B141 -> 0 | C14: ='DATA ROOM RUKOST'!G129 -> 2656800000 | D14: ='DATA ROOM RUKOST'!B129 -> 123
A15: ='DATA ROOM APARTKOST'!A49 -> INHOUSE | B15: ='DATA ROOM RUKOST'!B133 -> 0
A16: KOST PUTRA | B16: ='DATA ROOM RUKOST'!B136 -> 0
A17: KOST PUTRI | B17: ='DATA ROOM RUKOST'!B137 -> 0
A18: KOST PUTRA | B18: ='DATA ROOM RUKOST'!D136 -> 0
A19: KOST PUTRI | B19: ='DATA ROOM RUKOST'!D137 -> 0

Sheet DATA ROOM APARTKOST
A1: JUMLAH KAMAR | B1: NO. UNIT | C1: NO. KAMAR | D1: TENANT | E1: KELAMIN | F1: STATUS | G1: WAKTU SEWA/TAHUN | H1: RATE | I1: CHECK IN | J1: CHECK OUT | K1: TANGGAL BULAN 2026
A2: 1 | B2: 05A PUTRI | C2: 1 B | F2: =IF(D2="","Vacant","Inhouse") -> Vacant | H2: =G2*$G$44 -> 0 | K2: 1 | L2: 2 | M2: 3 | N2: 4 | O2: 5 | P2: 6 | Q2: 7 | R2: 8 | S2: 9 | T2: 10 | U2: 11 | V2: 12 | W2: 13 | X2: 14 | Y2: 15 | Z2: 16 | AA2: 17 | AB2: 18 | AC2: 19 | AD2: 20 | AE2: 21 | AF2: 22 | AG2: 23 | AH2: 24 | AI2: 25 | AJ2: 26 | AK2: 27 | AL2: 28 | AM2: 29 | AN2: 30 | AO2: 31
A3: 2 | C3: 2 B | F3: =IF(D3="","Vacant","Inhouse") -> Vacant | H3: =G3*$G$44 -> 0 | K3: 1 | L3: 2 | M3: 3 | N3: 4 | O3: 5 | P3: 6 | Q3: 7 | R3: 8 | S3: 9 | T3: 10 | U3: 11 | V3: 12 | W3: 13 | X3: 14 | Y3: 15 | Z3: 16 | AA3: 17 | AB3: 18 | AC3: 19 | AD3: 20 | AE3: 21 | AF3: 22 | AG3: 23 | AH3: 24 | AI3: 25 | AJ3: 26 | AK3: 27 | AL3: 28 | AM3: 29 | AN3: 30 | AO3: 31
A4: 3 | C4: 3 A | F4: =IF(D4="","Vacant","Inhouse") -> Vacant | H4: =G4*$G$44 -> 0 | K4: 1 | L4: 2 | M4: 3 | N4: 4 | O4: 5 | P4: 6 | Q4: 7 | R4: 8 | S4: 9 | T4: 10 | U4: 11 | V4: 12 | W4: 13 | X4: 14 | Y4: 15 | Z4: 16 | AA4: 17 | AB4: 18 | AC4: 19 | AD4: 20 | AE4: 21 | AF4: 22 | AG4: 23 | AH4: 24 | AI4: 25 | AJ4: 26 | AK4: 27 | AL4: 28 | AM4: 29 | AN4: 30 | AO4: 31
A5: 4 | C5: 4 A | F5: =IF(D5="","Vacant","Inhouse") -> Vacant | H5: =G5*$G$44 -> 0 | K5: 1 | L5: 2 | M5: 3 | N5: 4 | O5: 5 | P5: 6 | Q5: 7 | R5: 8 | S5: 9 | T5: 10 | U5: 11 | V5: 12 | W5: 13 | X5: 14 | Y5: 15 | Z5: 16 | AA5: 17 | AB5: 18 | AC5: 19 | AD5: 20 | AE5: 21 | AF5: 22 | AG5: 23 | AH5: 24 | AI5: 25 | AJ5: 26 | AK5: 27 | AL5: 28 | AM5: 29 | AN5: 30 | AO5: 31
A6: 5 | B6: 05B PUTRI | C6: 1 B | F6: =IF(D6="","Vacant","Inhouse") -> Vacant | H6: =G6*$G$44 -> 0 | K6: 1 | L6: 2 | M6: 3 | N6: 4 | O6: 5 | P6: 6 | Q6: 7 | R6: 8 | S6: 9 | T6: 10 | U6: 11 | V6: 12 | W6: 13 | X6: 14 | Y6: 15 | Z6: 16 | AA6: 17 | AB6: 18 | AC6: 19 | AD6: 20 | AE6: 21 | AF6: 22 | AG6: 23 | AH6: 24 | AI6: 25 | AJ6: 26 | AK6: 27 | AL6: 28 | AM6: 29 | AN6: 30 | AO6: 31
A7: 6 | C7: 2 B | F7: =IF(D7="","Vacant","Inhouse") -> Vacant | H7: =G7*$G$44 -> 0 | K7: 1 | L7: 2 | M7: 3 | N7: 4 | O7: 5 | P7: 6 | Q7: 7 | R7: 8 | S7: 9 | T7: 10 | U7: 11 | V7: 12 | W7: 13 | X7: 14 | Y7: 15 | Z7: 16 | AA7: 17 | AB7: 18 | AC7: 19 | AD7: 20 | AE7: 21 | AF7: 22 | AG7: 23 | AH7: 24 | AI7: 25 | AJ7: 26 | AK7: 27 | AL7: 28 | AM7: 29 | AN7: 30 | AO7: 31
A8: 7 | C8: 3 A | F8: =IF(D8="","Vacant","Inhouse") -> Vacant | H8: =G8*$G$44 -> 0 | K8: 1 | L8: 2 | M8: 3 | N8: 4 | O8: 5 | P8: 6 | Q8: 7 | R8: 8 | S8: 9 | T8: 10 | U8: 11 | V8: 12 | W8: 13 | X8: 14 | Y8: 15 | Z8: 16 | AA8: 17 | AB8: 18 | AC8: 19 | AD8: 20 | AE8: 21 | AF8: 22 | AG8: 23 | AH8: 24 | AI8: 25 | AJ8: 26 | AK8: 27 | AL8: 28 | AM8: 29 | AN8: 30 | AO8: 31
A9: 8 | C9: 4 A | F9: =IF(D9="","Vacant","Inhouse") -> Vacant | H9: =G9*$G$44 -> 0 | K9: 1 | L9: 2 | M9: 3 | N9: 4 | O9: 5 | P9: 6 | Q9: 7 | R9: 8 | S9: 9 | T9: 10 | U9: 11 | V9: 12 | W9: 13 | X9: 14 | Y9: 15 | Z9: 16 | AA9: 17 | AB9: 18 | AC9: 19 | AD9: 20 | AE9: 21 | AF9: 22 | AG9: 23 | AH9: 24 | AI9: 25 | AJ9: 26 | AK9: 27 | AL9: 28 | AM9: 29 | AN9: 30 | AO9: 31
A10: 9 | B10: 05C PUTRI | C10: 1 B | F10: =IF(D10="","Vacant","Inhouse") -> Vacant | H10: =G10*$G$44 -> 0 | K10: 1 | L10: 2 | M10: 3 | N10: 4 | O10: 5 | P10: 6 | Q10: 7 | R10: 8 | S10: 9 | T10: 10 | U10: 11 | V10: 12 | W10: 13 | X10: 14 | Y10: 15 | Z10: 16 | AA10: 17 | AB10: 18 | AC10: 19 | AD10: 20 | AE10: 21 | AF10: 22 | AG10: 23 | AH10: 24 | AI10: 25 | AJ10: 26 | AK10: 27 | AL10: 28 | AM10: 29 | AN10: 30 | AO10: 31
A11: 10 | C11: 2 B | F11: =IF(D11="","Vacant","Inhouse") -> Vacant | H11: =G11*$G$44 -> 0 | K11: 1 | L11: 2 | M11: 3 | N11: 4 | O11: 5 | P11: 6 | Q11: 7 | R11: 8 | S11: 9 | T11: 10 | U11: 11 | V11: 12 | W11: 13 | X11: 14 | Y11: 15 | Z11: 16 | AA11: 17 | AB11: 18 | AC11: 19 | AD11: 20 | AE11: 21 | AF11: 22 | AG11: 23 | AH11: 24 | AI11: 25 | AJ11: 26 | AK11: 27 | AL11: 28 | AM11: 29 | AN11: 30 | AO11: 31
A12: 11 | C12: 3 A | F12: =IF(D12="","Vacant","Inhouse") -> Vacant | H12: =G12*$G$44 -> 0 | K12: 1 | L12: 2 | M12: 3 | N12: 4 | O12: 5 | P12: 6 | Q12: 7 | R12: 8 | S12: 9 | T12: 10 | U12: 11 | V12: 12 | W12: 13 | X12: 14 | Y12: 15 | Z12: 16 | AA12: 17 | AB12: 18 | AC12: 19 | AD12: 20 | AE12: 21 | AF12: 22 | AG12: 23 | AH12: 24 | AI12: 25 | AJ12: 26 | AK12: 27 | AL12: 28 | AM12: 29 | AN12: 30 | AO12: 31
A13: 12 | C13: 4 A | F13: =IF(D13="","Vacant","Inhouse") -> Vacant | H13: =G13*$G$44 -> 0 | K13: 1 | L13: 2 | M13: 3 | N13: 4 | O13: 5 | P13: 6 | Q13: 7 | R13: 8 | S13: 9 | T13: 10 | U13: 11 | V13: 12 | W13: 13 | X13: 14 | Y13: 15 | Z13: 16 | AA13: 17 | AB13: 18 | AC13: 19 | AD13: 20 | AE13: 21 | AF13: 22 | AG13: 23 | AH13: 24 | AI13: 25 | AJ13: 26 | AK13: 27 | AL13: 28 | AM13: 29 | AN13: 30 | AO13: 31
A14: 13 | B14: 05D PUTRI | C14: 1 B | F14: =IF(D14="","Vacant","Inhouse") -> Vacant | H14: =G14*$G$44 -> 0 | K14: 1 | L14: 2 | M14: 3 | N14: 4 | O14: 5 | P14: 6 | Q14: 7 | R14: 8 | S14: 9 | T14: 10 | U14: 11 | V14: 12 | W14: 13 | X14: 14 | Y14: 15 | Z14: 16 | AA14: 17 | AB14: 18 | AC14: 19 | AD14: 20 | AE14: 21 | AF14: 22 | AG14: 23 | AH14: 24 | AI14: 25 | AJ14: 26 | AK14: 27 | AL14: 28 | AM14: 29 | AN14: 30 | AO14: 31
A15: 14 | C15: 2 B | F15: =IF(D15="","Vacant","Inhouse") -> Vacant | H15: =G15*$G$44 -> 0 | K15: 1 | L15: 2 | M15: 3 | N15: 4 | O15: 5 | P15: 6 | Q15: 7 | R15: 8 | S15: 9 | T15: 10 | U15: 11 | V15: 12 | W15: 13 | X15: 14 | Y15: 15 | Z15: 16 | AA15: 17 | AB15: 18 | AC15: 19 | AD15: 20 | AE15: 21 | AF15: 22 | AG15: 23 | AH15: 24 | AI15: 25 | AJ15: 26 | AK15: 27 | AL15: 28 | AM15: 29 | AN15: 30 | AO15: 31
A16: 15 | C16: 3 A | F16: =IF(D16="","Vacant","Inhouse") -> Vacant | H16: =G16*$G$44 -> 0 | K16: 1 | L16: 2 | M16: 3 | N16: 4 | O16: 5 | P16: 6 | Q16: 7 | R16: 8 | S16: 9 | T16: 10 | U16: 11 | V16: 12 | W16: 13 | X16: 14 | Y16: 15 | Z16: 16 | AA16: 17 | AB16: 18 | AC16: 19 | AD16: 20 | AE16: 21 | AF16: 22 | AG16: 23 | AH16: 24 | AI16: 25 | AJ16: 26 | AK16: 27 | AL16: 28 | AM16: 29 | AN16: 30 | AO16: 31
A17: 16 | C17: 4 A | F17: =IF(D17="","Vacant","Inhouse") -> Vacant | H17: =G17*$G$44 -> 0 | K17: 1 | L17: 2 | M17: 3 | N17: 4 | O17: 5 | P17: 6 | Q17: 7 | R17: 8 | S17: 9 | T17: 10 | U17: 11 | V17: 12 | W17: 13 | X17: 14 | Y17: 15 | Z17: 16 | AA17: 17 | AB17: 18 | AC17: 19 | AD17: 20 | AE17: 21 | AF17: 22 | AG17: 23 | AH17: 24 | AI17: 25 | AJ17: 26 | AK17: 27 | AL17: 28 | AM17: 29 | AN17: 30 | AO17: 31
A18: 17 | B18: 18A PUTRA | C18: 1 B | F18: =IF(D18="","Vacant","Inhouse") -> Vacant | H18: =G18*$G$44 -> 0 | K18: 1 | L18: 2 | M18: 3 | N18: 4 | O18: 5 | P18: 6 | Q18: 7 | R18: 8 | S18: 9 | T18: 10 | U18: 11 | V18: 12 | W18: 13 | X18: 14 | Y18: 15 | Z18: 16 | AA18: 17 | AB18: 18 | AC18: 19 | AD18: 20 | AE18: 21 | AF18: 22 | AG18: 23 | AH18: 24 | AI18: 25 | AJ18: 26 | AK18: 27 | AL18: 28 | AM18: 29 | AN18: 30 | AO18: 31
A19: 18 | C19: 2 B | F19: =IF(D19="","Vacant","Inhouse") -> Vacant | H19: =G19*$G$44 -> 0 | K19: 1 | L19: 2 | M19: 3 | N19: 4 | O19: 5 | P19: 6 | Q19: 7 | R19: 8 | S19: 9 | T19: 10 | U19: 11 | V19: 12 | W19: 13 | X19: 14 | Y19: 15 | Z19: 16 | AA19: 17 | AB19: 18 | AC19: 19 | AD19: 20 | AE19: 21 | AF19: 22 | AG19: 23 | AH19: 24 | AI19: 25 | AJ19: 26 | AK19: 27 | AL19: 28 | AM19: 29 | AN19: 30 | AO19: 31
A20: 19 | C20: 3 A | F20: =IF(D20="","Vacant","Inhouse") -> Vacant | H20: =G20*$G$44 -> 0 | K20: 1 | L20: 2 | M20: 3 | N20: 4 | O20: 5 | P20: 6 | Q20: 7 | R20: 8 | S20: 9 | T20: 10 | U20: 11 | V20: 12 | W20: 13 | X20: 14 | Y20: 15 | Z20: 16 | AA20: 17 | AB20: 18 | AC20: 19 | AD20: 20 | AE20: 21 | AF20: 22 | AG20: 23 | AH20: 24 | AI20: 25 | AJ20: 26 | AK20: 27 | AL20: 28 | AM20: 29 | AN20: 30 | AO20: 31
A21: 20 | C21: 4 A | F21: =IF(D21="","Vacant","Inhouse") -> Vacant | H21: =G21*$G$44 -> 0 | K21: 1 | L21: 2 | M21: 3 | N21: 4 | O21: 5 | P21: 6 | Q21: 7 | R21: 8 | S21: 9 | T21: 10 | U21: 11 | V21: 12 | W21: 13 | X21: 14 | Y21: 15 | Z21: 16 | AA21: 17 | AB21: 18 | AC21: 19 | AD21: 20 | AE21: 21 | AF21: 22 | AG21: 23 | AH21: 24 | AI21: 25 | AJ21: 26 | AK21: 27 | AL21: 28 | AM21: 29 | AN21: 30 | AO21: 31
A22: 21 | B22: 18B PUTRA | C22: 1 B | F22: =IF(D22="","Vacant","Inhouse") -> Vacant | H22: =G22*$G$44 -> 0 | K22: 1 | L22: 2 | M22: 3 | N22: 4 | O22: 5 | P22: 6 | Q22: 7 | R22: 8 | S22: 9 | T22: 10 | U22: 11 | V22: 12 | W22: 13 | X22: 14 | Y22: 15 | Z22: 16 | AA22: 17 | AB22: 18 | AC22: 19 | AD22: 20 | AE22: 21 | AF22: 22 | AG22: 23 | AH22: 24 | AI22: 25 | AJ22: 26 | AK22: 27 | AL22: 28 | AM22: 29 | AN22: 30 | AO22: 31
A23: 22 | C23: 2 B | F23: =IF(D23="","Vacant","Inhouse") -> Vacant | H23: =G23*$G$44 -> 0 | K23: 1 | L23: 2 | M23: 3 | N23: 4 | O23: 5 | P23: 6 | Q23: 7 | R23: 8 | S23: 9 | T23: 10 | U23: 11 | V23: 12 | W23: 13 | X23: 14 | Y23: 15 | Z23: 16 | AA23: 17 | AB23: 18 | AC23: 19 | AD23: 20 | AE23: 21 | AF23: 22 | AG23: 23 | AH23: 24 | AI23: 25 | AJ23: 26 | AK23: 27 | AL23: 28 | AM23: 29 | AN23: 30 | AO23: 31
A24: 23 | C24: 3 A | F24: =IF(D24="","Vacant","Inhouse") -> Vacant | H24: =G24*$G$44 -> 0 | K24: 1 | L24: 2 | M24: 3 | N24: 4 | O24: 5 | P24: 6 | Q24: 7 | R24: 8 | S24: 9 | T24: 10 | U24: 11 | V24: 12 | W24: 13 | X24: 14 | Y24: 15 | Z24: 16 | AA24: 17 | AB24: 18 | AC24: 19 | AD24: 20 | AE24: 21 | AF24: 22 | AG24: 23 | AH24: 24 | AI24: 25 | AJ24: 26 | AK24: 27 | AL24: 28 | AM24: 29 | AN24: 30 | AO24: 31
A25: 24 | C25: 4 A | F25: =IF(D25="","Vacant","Inhouse") -> Vacant | H25: =G25*$G$44 -> 0 | K25: 1 | L25: 2 | M25: 3 | N25: 4 | O25: 5 | P25: 6 | Q25: 7 | R25: 8 | S25: 9 | T25: 10 | U25: 11 | V25: 12 | W25: 13 | X25: 14 | Y25: 15 | Z25: 16 | AA25: 17 | AB25: 18 | AC25: 19 | AD25: 20 | AE25: 21 | AF25: 22 | AG25: 23 | AH25: 24 | AI25: 25 | AJ25: 26 | AK25: 27 | AL25: 28 | AM25: 29 | AN25: 30 | AO25: 31
A26: 25 | B26: 18C PUTRA | C26: 1 B | F26: =IF(D26="","Vacant","Inhouse") -> Vacant | H26: =G26*$G$44 -> 0 | K26: 1 | L26: 2 | M26: 3 | N26: 4 | O26: 5 | P26: 6 | Q26: 7 | R26: 8 | S26: 9 | T26: 10 | U26: 11 | V26: 12 | W26: 13 | X26: 14 | Y26: 15 | Z26: 16 | AA26: 17 | AB26: 18 | AC26: 19 | AD26: 20 | AE26: 21 | AF26: 22 | AG26: 23 | AH26: 24 | AI26: 25 | AJ26: 26 | AK26: 27 | AL26: 28 | AM26: 29 | AN26: 30 | AO26: 31
A27: 26 | C27: 2 B | F27: =IF(D27="","Vacant","Inhouse") -> Vacant | H27: =G27*$G$44 -> 0 | K27: 1 | L27: 2 | M27: 3 | N27: 4 | O27: 5 | P27: 6 | Q27: 7 | R27: 8 | S27: 9 | T27: 10 | U27: 11 | V27: 12 | W27: 13 | X27: 14 | Y27: 15 | Z27: 16 | AA27: 17 | AB27: 18 | AC27: 19 | AD27: 20 | AE27: 21 | AF27: 22 | AG27: 23 | AH27: 24 | AI27: 25 | AJ27: 26 | AK27: 27 | AL27: 28 | AM27: 29 | AN27: 30 | AO27: 31
A28: 27 | C28: 3 A | F28: =IF(D28="","Vacant","Inhouse") -> Vacant | H28: =G28*$G$44 -> 0 | K28: 1 | L28: 2 | M28: 3 | N28: 4 | O28: 5 | P28: 6 | Q28: 7 | R28: 8 | S28: 9 | T28: 10 | U28: 11 | V28: 12 | W28: 13 | X28: 14 | Y28: 15 | Z28: 16 | AA28: 17 | AB28: 18 | AC28: 19 | AD28: 20 | AE28: 21 | AF28: 22 | AG28: 23 | AH28: 24 | AI28: 25 | AJ28: 26 | AK28: 27 | AL28: 28 | AM28: 29 | AN28: 30 | AO28: 31
A29: 28 | C29: 4 A | F29: =IF(D29="","Vacant","Inhouse") -> Vacant | H29: =G29*$G$44 -> 0 | K29: 1 | L29: 2 | M29: 3 | N29: 4 | O29: 5 | P29: 6 | Q29: 7 | R29: 8 | S29: 9 | T29: 10 | U29: 11 | V29: 12 | W29: 13 | X29: 14 | Y29: 15 | Z29: 16 | AA29: 17 | AB29: 18 | AC29: 19 | AD29: 20 | AE29: 21 | AF29: 22 | AG29: 23 | AH29: 24 | AI29: 25 | AJ29: 26 | AK29: 27 | AL29: 28 | AM29: 29 | AN29: 30 | AO29: 31
A30: 29 | B30: 18D PUTRA | C30: 1 B | F30: =IF(D30="","Vacant","Inhouse") -> Vacant | H30: =G30*$G$44 -> 0 | K30: 1 | L30: 2 | M30: 3 | N30: 4 | O30: 5 | P30: 6 | Q30: 7 | R30: 8 | S30: 9 | T30: 10 | U30: 11 | V30: 12 | W30: 13 | X30: 14 | Y30: 15 | Z30: 16 | AA30: 17 | AB30: 18 | AC30: 19 | AD30: 20 | AE30: 21 | AF30: 22 | AG30: 23 | AH30: 24 | AI30: 25 | AJ30: 26 | AK30: 27 | AL30: 28 | AM30: 29 | AN30: 30 | AO30: 31
A31: 30 | C31: 2 B | F31: =IF(D31="","Vacant","Inhouse") -> Vacant | H31: =G31*$G$44 -> 0 | K31: 1 | L31: 2 | M31: 3 | N31: 4 | O31: 5 | P31: 6 | Q31: 7 | R31: 8 | S31: 9 | T31: 10 | U31: 11 | V31: 12 | W31: 13 | X31: 14 | Y31: 15 | Z31: 16 | AA31: 17 | AB31: 18 | AC31: 19 | AD31: 20 | AE31: 21 | AF31: 22 | AG31: 23 | AH31: 24 | AI31: 25 | AJ31: 26 | AK31: 27 | AL31: 28 | AM31: 29 | AN31: 30 | AO31: 31
A32: 31 | C32: 3 A | F32: =IF(D32="","Vacant","Inhouse") -> Vacant | H32: =G32*$G$44 -> 0 | K32: 1 | L32: 2 | M32: 3 | N32: 4 | O32: 5 | P32: 6 | Q32: 7 | R32: 8 | S32: 9 | T32: 10 | U32: 11 | V32: 12 | W32: 13 | X32: 14 | Y32: 15 | Z32: 16 | AA32: 17 | AB32: 18 | AC32: 19 | AD32: 20 | AE32: 21 | AF32: 22 | AG32: 23 | AH32: 24 | AI32: 25 | AJ32: 26 | AK32: 27 | AL32: 28 | AM32: 29 | AN32: 30 | AO32: 31
A33: 32 | C33: 4 A | F33: =IF(D33="","Vacant","Inhouse") -> Vacant | H33: =G33*$G$44 -> 0 | K33: 1 | L33: 2 | M33: 3 | N33: 4 | O33: 5 | P33: 6 | Q33: 7 | R33: 8 | S33: 9 | T33: 10 | U33: 11 | V33: 12 | W33: 13 | X33: 14 | Y33: 15 | Z33: 16 | AA33: 17 | AB33: 18 | AC33: 19 | AD33: 20 | AE33: 21 | AF33: 22 | AG33: 23 | AH33: 24 | AI33: 25 | AJ33: 26 | AK33: 27 | AL33: 28 | AM33: 29 | AN33: 30 | AO33: 31
A34: 33 | B34: 18E PUTRA | C34: 1 B | F34: =IF(D34="","Vacant","Inhouse") -> Vacant | H34: =G34*$G$44 -> 0 | K34: 1 | L34: 2 | M34: 3 | N34: 4 | O34: 5 | P34: 6 | Q34: 7 | R34: 8 | S34: 9 | T34: 10 | U34: 11 | V34: 12 | W34: 13 | X34: 14 | Y34: 15 | Z34: 16 | AA34: 17 | AB34: 18 | AC34: 19 | AD34: 20 | AE34: 21 | AF34: 22 | AG34: 23 | AH34: 24 | AI34: 25 | AJ34: 26 | AK34: 27 | AL34: 28 | AM34: 29 | AN34: 30 | AO34: 31
A35: 34 | C35: 2 B | F35: =IF(D35="","Vacant","Inhouse") -> Vacant | H35: =G35*$G$44 -> 0 | K35: 1 | L35: 2 | M35: 3 | N35: 4 | O35: 5 | P35: 6 | Q35: 7 | R35: 8 | S35: 9 | T35: 10 | U35: 11 | V35: 12 | W35: 13 | X35: 14 | Y35: 15 | Z35: 16 | AA35: 17 | AB35: 18 | AC35: 19 | AD35: 20 | AE35: 21 | AF35: 22 | AG35: 23 | AH35: 24 | AI35: 25 | AJ35: 26 | AK35: 27 | AL35: 28 | AM35: 29 | AN35: 30 | AO35: 31
A36: 35 | C36: 3 A | F36: =IF(D36="","Vacant","Inhouse") -> Vacant | H36: =G36*$G$44 -> 0 | K36: 1 | L36: 2 | M36: 3 | N36: 4 | O36: 5 | P36: 6 | Q36: 7 | R36: 8 | S36: 9 | T36: 10 | U36: 11 | V36: 12 | W36: 13 | X36: 14 | Y36: 15 | Z36: 16 | AA36: 17 | AB36: 18 | AC36: 19 | AD36: 20 | AE36: 21 | AF36: 22 | AG36: 23 | AH36: 24 | AI36: 25 | AJ36: 26 | AK36: 27 | AL36: 28 | AM36: 29 | AN36: 30 | AO36: 31
A37: 36 | C37: 4 A | F37: =IF(D37="","Vacant","Inhouse") -> Vacant | H37: =G37*$G$44 -> 0 | K37: 1 | L37: 2 | M37: 3 | N37: 4 | O37: 5 | P37: 6 | Q37: 7 | R37: 8 | S37: 9 | T37: 10 | U37: 11 | V37: 12 | W37: 13 | X37: 14 | Y37: 15 | Z37: 16 | AA37: 17 | AB37: 18 | AC37: 19 | AD37: 20 | AE37: 21 | AF37: 22 | AG37: 23 | AH37: 24 | AI37: 25 | AJ37: 26 | AK37: 27 | AL37: 28 | AM37: 29 | AN37: 30 | AO37: 31
A38: 37 | B38: 18F PUTRA | C38: 1 B | F38: =IF(D38="","Vacant","Inhouse") -> Vacant | H38: =G38*$G$44 -> 0 | K38: 1 | L38: 2 | M38: 3 | N38: 4 | O38: 5 | P38: 6 | Q38: 7 | R38: 8 | S38: 9 | T38: 10 | U38: 11 | V38: 12 | W38: 13 | X38: 14 | Y38: 15 | Z38: 16 | AA38: 17 | AB38: 18 | AC38: 19 | AD38: 20 | AE38: 21 | AF38: 22 | AG38: 23 | AH38: 24 | AI38: 25 | AJ38: 26 | AK38: 27 | AL38: 28 | AM38: 29 | AN38: 30 | AO38: 31
A39: 38 | C39: 2 B | F39: =IF(D39="","Vacant","Inhouse") -> Vacant | H39: =G39*$G$44 -> 0 | K39: 1 | L39: 2 | M39: 3 | N39: 4 | O39: 5 | P39: 6 | Q39: 7 | R39: 8 | S39: 9 | T39: 10 | U39: 11 | V39: 12 | W39: 13 | X39: 14 | Y39: 15 | Z39: 16 | AA39: 17 | AB39: 18 | AC39: 19 | AD39: 20 | AE39: 21 | AF39: 22 | AG39: 23 | AH39: 24 | AI39: 25 | AJ39: 26 | AK39: 27 | AL39: 28 | AM39: 29 | AN39: 30 | AO39: 31
A40: 39 | C40: 3 A | F40: =IF(D40="","Vacant","Inhouse") -> Vacant | H40: =G40*$G$44 -> 0 | K40: 1 | L40: 2 | M40: 3 | N40: 4 | O40: 5 | P40: 6 | Q40: 7 | R40: 8 | S40: 9 | T40: 10 | U40: 11 | V40: 12 | W40: 13 | X40: 14 | Y40: 15 | Z40: 16 | AA40: 17 | AB40: 18 | AC40: 19 | AD40: 20 | AE40: 21 | AF40: 22 | AG40: 23 | AH40: 24 | AI40: 25 | AJ40: 26 | AK40: 27 | AL40: 28 | AM40: 29 | AN40: 30 | AO40: 31
...

Sheet KPI DIAGRAM APARTKOST
A13: ='DATA ROOM APARTKOST'!A47 -> OCCUPANCY | B13: ='DATA ROOM APARTKOST'!C49 -> REVENUE | C13: ='DATA ROOM APARTKOST'!A58 -> TARGET | D13: ='DATA ROOM APARTKOST'!A51 -> TOTAL KAMAR
A14: ='DATA ROOM APARTKOST'!B47 -> 0 | B14: ='DATA ROOM APARTKOST'!D49 -> 0 | C14: ='DATA ROOM APARTKOST'!B58 -> 864000000 | D14: ='DATA ROOM APARTKOST'!B51 -> 40
A15: ='DATA ROOM APARTKOST'!A49 -> INHOUSE | B15: ='DATA ROOM APARTKOST'!B49 -> 0
A16: KOST PUTRA | B16: ='DATA ROOM APARTKOST'!B52 -> 0
A17: KOST PUTRI | B17: ='DATA ROOM APARTKOST'!B53 -> 0
A18: KOST PUTRA | B18: ='DATA ROOM APARTKOST'!D52 -> 0
A19: KOST PUTRI | B19: ='DATA ROOM APARTKOST'!D53 -> 0

Sheet Sheet6
A1: GSH JATINANGOR 1
A2: Type RuKost | D2: Type ApartKost | G2: GSH JATINANGOR 1
A3: Putra | B3: 57 | D3: Putra | E3: 24 | G3: Putra | H3: =B3+E3 -> 81
A4: Putri | B4: 66 | D4: Putri | E4: 16 | G4: Putri | H4: =B4+E4 -> 82
A5: Total | B5: 123 | D5: Total | E5: 40 | G5: Total | H5: =B5+E5 -> 163
A8: BUDGET | D8: BUDGET | G8: BUDGET
A9: ='KPI DIAGRAM RUKOST'!C14 -> 2656800000 | D9: ='KPI DIAGRAM APARTKOST'!C14 -> 864000000 | G9: =A9+D9 -> 3520800000
A10: OCCUPANCY | B10: ='KPI DIAGRAM RUKOST'!A14 -> 0 | D10: OCCUPANCY | E10: ='KPI DIAGRAM APARTKOST'!A14 -> 0 | G10: OCCUPANCY | H10: =B10+E10 -> 0
A11: REVENUE | B11: ='KPI DIAGRAM RUKOST'!B14 -> 0 | D11: REVENUE | E11: ='KPI DIAGRAM APARTKOST'!B14 -> 0 | G11: REVENUE | H11: =B11+E11 -> 0
A12: INHOUSE | B12: ='KPI DIAGRAM RUKOST'!B15 -> 0 | D12: INHOUSE | E12: ='KPI DIAGRAM APARTKOST'!B15 -> 0 | G12: INHOUSE | H12: =B12+E12 -> 0
A13: KOST PUTRA | B13: ='KPI DIAGRAM RUKOST'!B16 -> 0 | D13: KOST PUTRA | E13: ='KPI DIAGRAM APARTKOST'!B16 -> 0 | G13: KOST PUTRA | H13: =B13+E13 -> 0
A14: KOST PUTRI | B14: ='KPI DIAGRAM RUKOST'!B17 -> 0 | D14: KOST PUTRI | E14: ='KPI DIAGRAM APARTKOST'!B17 -> 0 | G14: KOST PUTRI | H14: =B14+E14 -> 0
A15: KOST PUTRA | B15: ='KPI DIAGRAM RUKOST'!B18 -> 0 | D15: KOST PUTRA | E15: ='KPI DIAGRAM APARTKOST'!B18 -> 0 | G15: KOST PUTRA | H15: =B15+E15 -> 0
A16: KOST PUTRI | B16: ='KPI DIAGRAM RUKOST'!B19 -> 0 | D16: KOST PUTRI | E16: ='KPI DIAGRAM APARTKOST'!B19 -> 0 | G16: KOST PUTRI | H16: =B16+E16 -> 0
